<robot name="gripper" xmlns:xacro="http://ros.org/wiki/xacro">

  <xacro:include filename="$(find rls_robot_description)/urdf/gripper/gripper.transmission.xacro"/>
  <xacro:include filename="$(find rls_robot_description)/urdf/gripper/gripper.gazebo.xacro"/>

  <xacro:arg name="gripper_parent" default="attachment_top"/>

  <!-- =============== Link =============== -->

  <link name="fixture_h">
    <visual>
    <inertial>
      <origin xyz="0 0 ${PI}" rpy="0 0 0" />
      <mass value="0.5" />
      <inertia ixx="0.015" ixy="0.000" ixz="0.000"
	                   iyy="0.014" iyz="-0.002"
	                               izz="0.01"/>
    </inertial>
      <origin rpy="0 0 0" xyz="0 0 0.051"/>
      <geometry>
        <mesh filename="package://rls_robot_description/meshes/stl/NewHandFixture.stl"/>
      </geometry>
      <material name="black_m"/>
    </visual>
    <collision>
      <origin rpy="0 0 0" xyz="0 0 0.051"/>
      <geometry>
        <mesh filename="package://rls_robot_description/meshes/stl/NewHandFixture.stl"/>
      </geometry>
    </collision>
  </link>

  <link name="gripper">
    <inertial>
      <origin xyz="0 0 ${PI}" rpy="0 0 0" />
      <mass value="0.5" />
      <inertia ixx="0.015" ixy="0.000" ixz="0.000"
	                   iyy="0.014" iyz="-0.002"
	                               izz="0.01"/>
    </inertial>
    <visual>
      <origin rpy="0 0 0" xyz="0 0 0"/>
      <geometry>
        <mesh filename="package://rls_robot_description/meshes/dae/gripper.dae"/>
      </geometry>
    </visual>
    <collision>
      <origin rpy="0 0 0" xyz="0 0 0"/>
      <geometry>
        <mesh filename="package://rls_robot_description/meshes/stl/hand.stl"/>
      </geometry>
    </collision>
  </link>

  <link name="finger_middle"/>

  <link name="finger_tip"/>

  <xacro:macro name="finger_link" params="name mesh mass *root_origin">
    <link name="root_finger_${name}">
      <inertial>
        <xacro:insert_block name="root_origin"/>
	<mass value="0.002" />
      	<inertia
            ixx="3.30140945222581E-06" ixy="6.88214269644119E-22" ixz="1.69538938348869E-20"
                                       iyy="2.38014886911173E-06" iyz="-3.12343399300023E-21"
                                                                  izz="1.52846665341064E-06" />
      </inertial>
      <visual>
        <xacro:insert_block name="root_origin"/>
	<geometry>
          <mesh filename="package://rls_robot_description/meshes/stl/rootFinger.stl"/>
	</geometry>
	<material name="black_m"/>
      </visual>
      <collision>
        <xacro:insert_block name="root_origin"/>
	<geometry>
          <mesh filename="package://rls_robot_description/meshes/stl/rootFinger.stl"/>
	</geometry>
      </collision>
    </link>

    <link name="finger_${name}">
      <inertial>
	<origin rpy="0 0 0" xyz="0 0 0"/>
	<mass value="${mass}" />
	<inertia
            ixx="3.30140945222581E-06" ixy="6.88214269644119E-22" ixz="1.69538938348869E-20" 
                                       iyy="2.38014886911173E-06" iyz="-3.12343399300023E-21" 
                                                                  izz="1.52846665341064E-06" /> 
      </inertial>
      <visual>
	<origin rpy="0 0 0" xyz="0 0 0"/>
	<geometry>
          <mesh filename="package://rls_robot_description/meshes/stl/finger${mesh}.stl"/>
	</geometry>
	<material name="right_blue"/>
      </visual>
      <collision>
	<origin rpy="0 0 0" xyz="0 0 0"/>
	<geometry>
          <mesh filename="package://rls_robot_description/meshes/stl/finger${mesh}.stl"/>
	</geometry>
      </collision>
    </link>
  </xacro:macro>

  <xacro:finger_link name="left" mesh="1" mass="0.01">
    <origin rpy="0 0 ${PI}" xyz="0 0 0" />
  </xacro:finger_link>
  <xacro:finger_link name="right" mesh="2" mass="0.0168898172009748">
    <origin rpy="0 0 0" xyz="0 0 0"/>
  </xacro:finger_link>

  <!-- ===============  Joint =============== -->

  <joint name="fixed_7" type="fixed">
    <parent link="$(arg gripper_parent)"/>
    <child link="fixture_h"/>
    <origin xyz="0 0 -0.05" rpy="0 0 0" />
  </joint>

  <joint name="fixed_8" type="fixed">
    <parent link="fixture_h"/>
    <child link="gripper"/>
    <origin rpy="0 0 0" xyz="0 0 0.051"/>
  </joint>

  <joint name="finger_middle_fixed" type="fixed">
    <parent link="gripper"/>
    <child link="finger_middle"/>
    <origin rpy="0 0 0" xyz="0 0 0.139"/>
  </joint>

  <joint name="finger_tip_fixed" type="fixed">
    <parent link="gripper"/>
    <child link="finger_tip"/>
    <origin rpy="0 0 0" xyz="0 0 0.164"/>
  </joint>

  <xacro:macro name="finger_joint" params="name *origin *limit *fixed_origin">
    <joint name="prismatic_finger_${name}" type="prismatic">
      <parent link="gripper"/>
      <child link="root_finger_${name}"/>
      <xacro:insert_block name="origin"/>
      <axis xyz="0 1 0"/>
      <xacro:insert_block name="limit"/>
      <!-- <mimic joint="prismatic_finger_${name}" multiplier="-1" offset="0"/> -->
      <!-- <dynamics damping="0.1" friction="0.01"/> -->
    </joint>

    <joint name="finger_${name}_fixed" type="fixed">
      <parent link="root_finger_${name}"/>
      <child link="finger_${name}"/>
      <axis xyz="0 1 0"/>
      <xacro:insert_block name="fixed_origin"/>
    </joint>
  </xacro:macro>

  <xacro:finger_joint name="left">
    <origin xyz="0 0.035 0.093" rpy="0 0 0"/>
    <limit effort="1000.0" lower="-0.035" upper="0.0" velocity="0.41887902"/>
    <origin rpy="0 0 0" xyz="0 -0.004 0.0705"/>
  </xacro:finger_joint>

  <xacro:finger_joint name="right">
    <origin xyz="0 -0.035 0.093" rpy="0 0 0"/>
    <limit effort="1000.0" lower="0.0" upper="0.035" velocity="0.41887902"/>
    <origin rpy="0 0 0" xyz="0 -0.014 0.0705"/>
  </xacro:finger_joint>

  <!-- =============== Transmission =============== -->
  <xacro:gripper_transmission name="left" reduction="1"/>
  <xacro:gripper_transmission name="right" reduction="1"/>

  <!-- =============== Gazobo =============== -->
  <xacro:gripper_gazebo name="left"/>
  <xacro:gripper_gazebo name="right"/>

</robot>
